Workbook

Sheet 設定・結論
A1: Threads 30日投稿設計｜倫子（@rinko_mind）
A2: 作成日 2026-10-12｜ChatGPT分析（競合レポート・100投稿案）＋自己分析（壁打ちメモ）を統合
A4: 投稿開始日（ここを変えると全日付が連動） | B4: 46308 | C4: ← 黄色セル＝入力欄。30日スケジュールの「結果」列も黄色セルに数値を入れてください。
A6: ■ コンセプト（結論）
A7: ポジション | B7: 「潜在意識を教える人」ではなく「ポジティブが効かなかった超ネガティブな人に、本音を吐く→現実に戻る→望む世界を描く“順番”を教える人」
A8: キャッチ | B8: ポジティブになれない人専用｜本音を吐いて、現実に戻り、望む世界を描くノート術
A9: 倫子式の順番 | B9: ①毒出し3分（吐く）→②一番強い感情を1語で囲む→③事実と脚本を分ける→④「ある」を3つ（払えた・食べた・眠れた）→⑤本当はどうしてほしかった？→⑥五感で妄想→⑦今日の1ミリ行動
A10: 名称 | B10: 「シネシネワーク」は体験談の中だけで使用。表の名前は「毒出し3分」「誰にも見せない本音ノート」に統一（誤解・配信制限リスク回避）
A11: プロフィール案 | B11: ポジティブになれない人専用｜本音を吐いて、現実に戻り、望む世界を描くノート術｜投資詐欺700万・占い依存・脳梗塞を経て「大丈夫なふり」を卒業｜個別相談（伴走型）はリンクから
A12: 固定投稿 | B12: Day3/14の「毒出し→3分本音ノート」をまとめ直し、「全7ステップ」＋個別相談リンクを置く（各投稿の「プロフ誘導」の受け皿）
A13: ゴール | B13: 14日で認知（閲覧・フォロー）→15〜30日で信頼（保存・DM）→Day30で個別相談（伴走型コーチング）へ
A15: ■ 投稿比率（30日スケジュールから自動集計）
A16: 柱 | B16: 本数 | C16: 比率 | D16: 目標比率
A17: 本音暴露 | B17: =COUNTIF(30日スケジュール!$D$5:$D$34,A17) -> 11 | C17: =IFERROR(B17/$B$22,0) -> 0.36666667 | D17: 0.4
A18: 界隈への違和感 | B18: =COUNTIF(30日スケジュール!$D$5:$D$34,A18) -> 7 | C18: =IFERROR(B18/$B$22,0) -> 0.23333333 | D18: 0.3
A19: ノート実演 | B19: =COUNTIF(30日スケジュール!$D$5:$D$34,A19) -> 6 | C19: =IFERROR(B19/$B$22,0) -> 0.2 | D19: 0.2
A20: 妄想への橋渡し | B20: =COUNTIF(30日スケジュール!$D$5:$D$34,A20) -> 3 | C20: =IFERROR(B20/$B$22,0) -> 0.1 | D20: 0.1
A21: 恋愛（依存） | B21: =COUNTIF(30日スケジュール!$D$5:$D$34,A21) -> 3 | C21: =IFERROR(B21/$B$22,0) -> 0.1 | D21: 10〜15%（恋愛は本音暴露枠から振替）
A22: 合計 | B22: =SUM(B17:B21) -> 30
A24: ■ 成果サマリー（30日スケジュールの結果欄から自動集計）
A25: 期間 | B25: 総閲覧 | C25: 総いいね | D25: 総返信 | E25: フォロー増 | F25: プロフ遷移 | G25: 反応率 | H25: フォロー転換率
A26: Day1〜14（認知・最優先） | B26: =SUM(30日スケジュール!Q5:Q18) -> 0 | C26: =SUM(30日スケジュール!R5:R18) -> 0 | D26: =SUM(30日スケジュール!S5:S18) -> 0 | E26: =SUM(30日スケジュール!U5:U18) -> 0 | F26: =SUM(30日スケジュール!V5:V18) -> 0 | G26: =IFERROR((C26+D26+SUM(30日スケジュール!T5:T18))/B26,0) -> 0 | H26: =IFERROR(E26/B26,0) -> 0
A27: Day15〜30（信頼・導線） | B27: =SUM(30日スケジュール!Q19:Q34) -> 0 | C27: =SUM(30日スケジュール!R19:R34) -> 0 | D27: =SUM(30日スケジュール!S19:S34) -> 0 | E27: =SUM(30日スケジュール!U19:U34) -> 0 | F27: =SUM(30日スケジュール!V19:V34) -> 0 | G27: =IFERROR((C27+D27+SUM(30日スケジュール!T19:T34))/B27,0) -> 0 | H27: =IFERROR(E27/B27,0) -> 0
A28: 30日合計 | B28: =SUM(30日スケジュール!Q5:Q34) -> 0 | C28: =SUM(30日スケジュール!R5:R34) -> 0 | D28: =SUM(30日スケジュール!S5:S34) -> 0 | E28: =SUM(30日スケジュール!U5:U34) -> 0 | F28: =SUM(30日スケジュール!V5:V34) -> 0 | G28: =IFERROR((C28+D28+SUM(30日スケジュール!T5:T34))/B28,0) -> 0 | H28: =IFERROR(E28/B28,0) -> 0
A30: ■ シートの使い方
A31: 1. 「30日スケジュール」：毎日の投稿文（1投稿目＋スレッド続き）、冒頭A/B/C（衝撃の事実・常識破壊・場面告白）。Day1〜14はピンク＝最優先期間。
A32: 2. 冒頭はA→B→Cのどれか1つを1行目に置き換えるだけで使えます。迷ったらA（衝撃の事実）。同じテーマの再投稿時に別案を使って比較。
A33: 3. 投稿後24時間の数値を黄色セル（閲覧・いいね・返信・リポスト・フォロー増・プロフ遷移）に入力→反応率が自動計算されます。
A34: 4. 「構造パターン」：標準構造と、プロフィールリンクのクリックが見込める別構造（S1〜S8）の文章の順番。
A35: 5. 「バズ投稿100」：前回案と重複しない新しい100本（冒頭2案ずつ）。31日目以降はここから補充。
A36: 6. 「分析まとめ」「競合バズ分析」「生々しいネタ」「浅い悩み・深い悩み」「恋愛・復縁判定」：ChatGPT分析を整理したもの。
A37: ※ 競合の閲覧数はChatGPTレポート（2026-10-12調査時点）の記載値で、本シート作成時に再計測はしていません。

Sheet 30日スケジュール
A1: 30日投稿スケジュール（Day1〜14＝最優先・認知期／Day15〜30＝信頼・導線期）
A2: 冒頭A＝衝撃の事実／B＝常識破壊／C＝場面・告白。1行目だけ差し替えて使用。黄色＝投稿後に入力。
A4: Day | B4: 日付 | C4: 時間 | D4: 柱 | E4: 悩みの深さ | F4: テーマ | G4: 冒頭A（衝撃の事実） | H4: 冒頭B（常識破壊） | I4: 冒頭C（場面・告白） | J4: 本文①（1投稿目・冒頭の後に続ける） | K4: 本文②（スレッド続き） | L4: コメント誘導（最後の1行） | M4: プロフ誘導 | N4: 構造 | O4: 参考にした競合・実績 | P4: 検証ポイント | Q4: 閲覧 | R4: いいね | S4: 返信 | T4: リポスト | U4: フォロー増 | V4: プロフ遷移 | W4: 反応率 | X4: メモ
A5: 1 | B5: =設定・結論!$B$4+0 -> 46308 | C5: 21:00 | D5: 界隈への違和感 | E5: 浅→深 | F5: アファメーションが効かなかった | G5: 「ありがとう」「大丈夫」「私はできる」を3年唱えた。現実は1ミリも変わらなかった。 | H5: アファメーションが効かないのは、回数が足りないからじゃない。 | I5: 毎朝、鏡の前で「私は愛されてる」と唱えながら、心の中で「嘘つけ」とつっこんでいた。 | J5: 毎朝、鏡の前で唱えてた。 「私は愛されてる」 「お金はどんどん入ってくる」 でも唱えながら、心の中では毎回 「嘘つけ」ってつっこんでた。 口は前向き。腹の中は真逆。 私の潜在意識が聞いていたのは、 口じゃなくて“腹の声”の方だったと思う。 だから、唱えるのをやめた。 | K5: 代わりにノートに書いたのは 「正直、全部ムカつく」 「なんで私だけ叶わないの」 きれいじゃない本音を出し切ったら、 不思議と“いい言葉”が嘘っぽくなくなった。 ポジティブになれない人は、 ダメなんじゃなくて順番が逆なだけ。 ①本音を吐く →②事実と分ける →③それから望む世界を描く | L5: 唱えながら、心の中でつっこんだことある？「嘘つけ」派の人、正直に教えて。 | M5: なし（初日はコメント獲得に集中） | N5: S2 告白反転型 | O5: 旧アカ1,511閲覧の再現／@fufu___life（界隈の常識否定） | P5: 旧アカの勝ちテーマが新アカでも再現するか | W5: =IF(Q5>0,(R5+S5+T5)/Q5,"")
A6: 2 | B6: =設定・結論!$B$4+1 -> 46309 | C6: 12:15 | D6: 本音暴露 | E6: 浅 | F6: 断れない食事・他人軸 | G6: 60代のおじさんに誘われて、行きたくもない焼肉に行った。肉を焼き、サラダを取り分け、自慢話に笑った。 | H6: 「誘ってくれたんだから行かなきゃ悪い」は、優しさじゃなかった。 | I6: 帰りの電車で、私は自分のことが大嫌いになっていた。 | J6: 誘ってくれたんだから、断ったら悪いかな。 そう思って行った焼肉。 肉を焼いて、サラダを取り分けて、 自慢話にニコニコうなずいて、 私のことを否定されても「そうですよね」。 帰り道、ぐったりして思った。 私、今日だれの人生を生きてたんだろう。 | K6: 「自分軸、持ってるけど？」って思ってた私が、 いちばん他人軸だった。 今は、行きたくない食事は秒で断る。 選ぶ基準はひとつだけ。 「今の私にとって、どっちが最高？」 ちなみにそのおじさん、 断っても断っても誘ってくる。メンタル最強。 | L6: 行きたくないのに行った食事、ある？誰と行ったかだけでいいから教えて。 | M6: なし | N6: S1 場面告白型 | O6: @mikari_neisan（整ったふり×生々しさ） | P6: 生々しい他人軸エピソードのコメント率 | W6: =IF(Q6>0,(R6+S6+T6)/Q6,"")
A7: 3 | B7: =設定・結論!$B$4+2 -> 46310 | C7: 21:30 | D7: ノート実演 | E7: 浅 | F7: 毒出しノート（強い感情入口） | G7: 感謝ノートに感謝が1行も書けなかった日、私は「ふざけんな」と書いた。 | H7: ジャーナリングの1行目は、きれいな言葉じゃなくていい。 | I7: 人には絶対に見せられないノートが、1冊だけある。 | J7: 感謝ノートを開いても、 「ありがとう」が1文字も出てこない日があった。 書けない自分を責めるくらいなら、と その日の1行目に書いたのが 「ふざけんな」 そこから3分、止まらなかった。 人のせい、嫉妬、悪口、全部。 | K7: 書き終わったら、頭の中が静かになってた。 私はこれを、こっそり “毒出し3分”と呼んでいる。 ルールは3つだけ。 ・誰にも見せない ・きれいにまとめない ・最後に一番強い感情を1語で丸で囲む 吐き出しっぱなしにしないのがコツ。続きはまた書くね。 | L7: あなたのノートの1行目、今日書くなら何て書く？ | M7: 「毒出しの次にやること」はプロフィールの固定投稿にまとめてます | N7: S1 場面告白型 | O7: @grit_power00（ジャーナリング否定から入る） | P7: Day14（実用型）との比較：感情入口 vs 実用入口 | W7: =IF(Q7>0,(R7+S7+T7)/Q7,"")
A8: 4 | B8: =設定・結論!$B$4+3 -> 46311 | C8: 21:00 | D8: 本音暴露 | E8: 深 | F8: 身体に出た代償・顔色を読む | G8: 脳梗塞で入院した時、人生で初めて「誰の顔色も読まなくていい時間」ができた。 | H8: 「気が利く人」は、才能じゃなくて生き延びるための癖だった。 | I8: 病院のベッドで、ホッとしている自分がいた。それが一番ショックだった。 | J8: 脳梗塞で入院した。 怖かった。 でも正直に言うと、 ホッとしている自分もいた。 誰の機嫌も取らなくていい。 「私がやります」と言わなくていい。 顔色を読まなくていい。 それが、病院のベッドだった。 | K8: 私はずっと 「気が利く」「しっかりしてる」と言われてきた。 でもそれは才能じゃなくて、 人の機嫌を読まないと怖かった頃の癖だった。 身体が止めてくれなかったら、 たぶん今も笑って無理してた。 ※体調の異変はがまんせず、すぐ医療機関へ。 | L8: 「しっかりしてるね」と言われて、本当はしんどかったことある？ | M8: なし | N8: S2 告白反転型 | O8: 現アカ1位1,137閲覧の再現 | P8: 過去1位テーマを強化冒頭で再投稿したときの伸び | W8: =IF(Q8>0,(R8+S8+T8)/Q8,"")
A9: 5 | B9: =設定・結論!$B$4+4 -> 46312 | C9: 21:00 | D9: 界隈への違和感 | E9: 深 | F9: ワクワク強要・お金 | G9: どうせ最後まで読む人は少ないので、本当のことを書きます。「ワクワクに従え」で、私は貯金を溶かした。 | H9: 「ワクワクする方を選べば叶う」は、超ネガティブな人には逆効果だった。 | I9: ワクワクしなきゃと思って申し込んだ講座。振り込んだ夜、私は布団の中で震えていた。 | J9: 「ワクワクする方を選べば叶う」 そう信じて、講座も占いもセミナーも申し込んだ。 振り込んだ直後だけ、ワクワクする。 でもその夜には 「また無駄にしたかも」と眠れない。 私がワクワクだと思っていたのは、 不安から逃げたいだけの焦りだった。 | K9: ネガティブが強い人ほど、 “ワクワク”と“焦り”の区別がつかない。 今の私の基準は 「ワクワクするか」じゃなくて 「選んだ後、呼吸が深いか」。 お金を使った後に絶望する人は、 あなたがダメなんじゃなくて、基準が合ってなかっただけ。 | L9: お金を使った後に「やっちゃった」って絶望したこと、ある？ | M9: なし | N9: S8 秘密暴露型 | O9: @fufu___life 59,821閲覧（同型） | P9: 秘密暴露型冒頭の読了率・保存 | W9: =IF(Q9>0,(R9+S9+T9)/Q9,"")
A10: 6 | B10: =設定・結論!$B$4+5 -> 46313 | C10: 07:30 | D10: 本音暴露 | E10: 浅 | F10: 人に頼れない | G10: 消しゴムは借りられる。でも「これお願い」が、死ぬほど言えなかった。 | H10: 「自分でやった方が早い」は、優秀さじゃない。 | I10: 「私がやります」と笑いながら、心の中ではずっとイライラしていた。 | J10: 消しゴムは借りられる。 ペンも借りられる。 でも仕事となると、 「これお願いしていい？」が言えない。 頼んだ後、頭の中で 「そんなこともできないの？」と言われる妄想が止まらないから。 | K10: だから全部自分でやる。 そして「なんで私ばっかり」とイライラする。 人に頼れない人は、性格が悪いんじゃない。 頼むことと、見捨てられることが 頭の中でつながっているだけ。 今日は、どうでもいい小さなことを1つだけ頼んでみて。 | L10: 頼めないのは「仕事」「家事」「お金」どれが一番？ | M10: なし | N10: S1 場面告白型 | O10: 現アカ2位728閲覧の再現 | P10: 朝投稿の反応確認 | W10: =IF(Q10>0,(R10+S10+T10)/Q10,"")
A11: 7 | B11: =設定・結論!$B$4+6 -> 46314 | C11: 21:00 | D11: ノート実演 | E11: 浅 | F11: ジャーナリングで何を書くか | G11: ジャーナリングを900日続けた人がいる。私は3日で挫折した。理由は「何を書けばいいかわからない」だった。 | H11: ジャーナリングで「今日の感謝」から書く人ほど、続かない。 | I11: ノートを開いて、ペンを持って、10分何も書けなかった。 | J11: ジャーナリング、何を書けばいいかわからない人へ。 🥉やめとけ：今日の感謝を3つ （ネガティブな日は嘘になる） 🥈無難：今日あったこと （日記で終わる） 🥇ネガティブが強い人に効いた： 「今、一番ムカついてるのは誰？」 | K11: 本音に一番近い感情から書くと、ペンが止まらない。 そのあとに続ける質問はこの2つ。 ・本当は、どうしてほしかった？ ・それが叶ったら、私はどんな顔してる？ 3つ目の質問で、はじめて「望み」が出てくる。 保存して、今夜1つだけやってみて。 | L11: ①②③どれから書く？番号だけでもOK。 | M11: 3つの質問のノートテンプレはプロフィールから受け取れます | N11: S3 ランキング比較型 | O11: @grit_power00 109,121閲覧（ランキング型）／@mirai.melife | P11: 保存・プロフ遷移（実用ランキングの効果） | W11: =IF(Q11>0,(R11+S11+T11)/Q11,"")
A12: 8 | B12: =設定・結論!$B$4+7 -> 46315 | C12: 21:00 | D12: 本音暴露 | E12: 深 | F12: 潜在意識講座の落ちこぼれ | G12: 潜在意識の先生に「もうあなたには教えられない」と言われた。 | H12: 潜在意識の講座で優等生だった人ほど、変われていなかった。 | I12: 講座の中で、私だけがいつも怒られていた。 | J12: 潜在意識の講座で、 私だけいつも怒られていた。 優秀なメンバーと比べられて、 最後に先生に言われた。 「もうあなたには教えられない。自己流でやりすぎ」 その時の本音は、反省じゃなかった。 「なんで私だけ」だった。 | K12: でも、どんなにエゴが騒いでも 幸せな自分だけは諦めなかった。 性格の悪い考えが出ても、 それを否定せずにノートに書いた。 落ちこぼれの私が、何をしてどう変わったか。 この話は【落ちこぼれ編】として続きを書きます。（1/3） | L12: 習い事や講座で「私だけできない」と思ったこと、ある？ | M12: 続き（2/3・3/3）はプロフィールからまとめて読めます | N12: S4 連載・未完ループ型 | O12: @yamakawa.nobuto（未完の一行→答えを隠す） | P12: 連載型がプロフ遷移を生むか | W12: =IF(Q12>0,(R12+S12+T12)/Q12,"")
A13: 9 | B13: =設定・結論!$B$4+8 -> 46316 | C13: 21:00 | D13: 界隈への違和感 | E13: 深 | F13: 妄想 vs 現実の時間差 | G13: 1日3分の妄想。残りの23時間57分、私は不安に浸かっていた。 | H13: 「1日数分イメージすれば叶う」は、超ネガティブな人には足りない。 | I13: 妄想を終えて目を開けた瞬間、通帳の数字が頭に浮かんだ。 | J13: 朝3分、叶った自分を妄想する。 目を開ける。 そこから23時間57分、 「お金どうしよう」「嫌われたかも」が流れ続ける。 3分 vs 23時間57分。 勝てるわけがなかった。 | K13: 妄想が足りないんじゃない。 雑念の方が、私の日常だった。 だから私は先に、23時間57分の方を片づけた。 不安を全部ノートに吐く。 事実と妄想を分ける。 それから3分の妄想に入る。 同じ3分でも、入り方を変えたら“浸れる”ようになった。 | L13: 妄想中に入ってくる雑念、一番多いのは何？ | M13: なし | N13: S2 告白反転型 | O13: @sora411114（向き合う人ほど変われない逆説） | P13: 妄想・潜在意識テーマの反応 | W13: =IF(Q13>0,(R13+S13+T13)/Q13,"")
A14: 10 | B14: =設定・結論!$B$4+9 -> 46317 | C14: 22:00 | D14: 恋愛（依存） | E14: 深 | F14: 占い依存 | G14: 彼から連絡が来ない1週間で、占いに8回お金を払った。 | H14: 占いで「戻ってくる」と言われても、不安は1ミリも消えなかった。 | I14: 深夜2時、3人目の占い師に同じ質問をしていた。 | J14: 彼から連絡が来ない。 不安で、占いに行く。 「大丈夫、戻ってきます」 ホッとするのは、その日の夜まで。 翌朝にはまた不安で、別の占い師へ。 1週間で8回。 欲しかったのは彼の気持ちじゃなかった。 | K14: 本当に欲しかったのは、 「私は大丈夫」と自分で思える感覚だった。 彼の気持ちは何回でも聞きに行くのに、 自分の気持ちは1回も聞いていなかった。 今夜は占いの前に、ノートに1行だけ。 「私は本当は、どうしたい？」 | L14: 不安な夜、あなたは何をしてしまう？占い・SNS監視・友達に連絡… | M14: なし | N14: S1 場面告白型 | O14: 恋愛テーマ検証（全体の10〜15％枠） | P14: 恋愛依存テーマの需要（復縁を直接は扱わない） | W14: =IF(Q14>0,(R14+S14+T14)/Q14,"")
A15: 11 | B15: =設定・結論!$B$4+10 -> 46318 | C15: 21:00 | D15: 本音暴露 | E15: 深 | F15: 感謝より自分の本音 | G15: どうせ最後まで読む人は少ないので本音を書きます。家族への感謝より、「自分で稼いで自由にしてる私、最高」の方が本音だった。 | H15: 「まず周りに感謝しましょう」が、私の本音を消していた。 | I15: 先生の前で「自由にさせてくれる家族に感謝です」と言った。心にもなかった。 | J15: 一人で出雲大社に行った。 道中からずっとワクワクしてた。 潜在意識の先生の前では 「自由にさせてくれる家族に感謝です」 って言わなきゃと思って、言った。 でも本音は、ただひとつ。 「自分で稼いで、自由にしてる私、最高！！」 | K15: 感謝は大事。 でも本音にフタをして言う感謝は、 私には“いい人の演技”だった。 私が正解と思ったら、それが正解。 そう決めたら、人の目がどうでもよくなった。 性格悪いと思われてもいい。これが本音。 | L15: 「本当はこっちが本音」っていう、言えないこと1つ教えて。 | M15: なし | N15: S8 秘密暴露型 | O15: @fufu___life（秘密告白）／@mikari_neisan | P15: 本音暴露のコメント・リポスト率 | W15: =IF(Q15>0,(R15+S15+T15)/Q15,"")
A16: 12 | B16: =設定・結論!$B$4+11 -> 46319 | C16: 21:00 | D16: ノート実演 | E16: 浅 | F16: 吐き出しの注意点 | G16: 「ネガティブを書き出すと逆に苦しくなる」は、半分正解だった。 | H16: 毒を吐くだけのノートは、ぐるぐるを強くする。 | I16: 悪口を書いたあと、余計にイライラして眠れなかった夜がある。 | J16: ネガティブを吐き出したら 余計に苦しくなった人へ。 それ、あなたのやり方が悪いんじゃない。 “吐きっぱなし”だっただけ。 私も最初は、書くほどムカついて眠れなかった。 | K16: 変わったのは、最後に3つ足してから。 ①一番強い感情を1語で囲む（怒り・怖い・寂しい） ②「事実」と「頭の中のストーリー」に線を引く ③今日“あった”ものを1つ書く（払えた・食べた・眠れた） 吐く→囲む→分ける→ある。 ここまでで1セット。 ※つらさが強い時は、一人で抱えず専門家にも相談してね。 | L16: 書き出して楽になった派？しんどくなった派？ | M16: 吐き出しの全7ステップは固定投稿にあります | N16: S6 Q&A反論型 | O16: @grit_power00（吐くだけではダメ論）への設計回答 | P16: 注意点投稿の信頼度（保存・フォロー転換） | W16: =IF(Q16>0,(R16+S16+T16)/Q16,"")
A17: 13 | B17: =設定・結論!$B$4+12 -> 46320 | C17: 12:15 | D17: 本音暴露 | E17: 深 | F17: 一人旅・人の目 | G17: 一人で出雲大社に行って気づいた。人といる時の方が、ずっと寂しかった。 | H17: 「一人＝寂しい人」と思っていたのは、私自身だった。 | I17: 一人で飲食店に入る。昔の私は、それすらできなかった。 | J17: 一人で出雲大社に行った。 一人でご飯屋さんに入って、 食べ歩きして、ゆっくり参拝して。 めちゃくちゃ贅沢な時間だった。 昔の私なら、 「ぼっちって思われてない？」 ってそればかり気にしてた。 | K17: 人から見られる自分が本当の私だと思って、 背伸びしまくってた。 人と合わせないと嫌われる。 友達とつるんでないと価値がない。 その思い込みでガチガチだった。 一人で満たされてみて初めてわかった。 人に合わせてた時の方が、ずっと寂しかった。 | L17: 一人で行けるのはどこまで？カフェ・ご飯・焼肉・旅行 | M17: なし | N17: S2 告白反転型 | O17: @yama_reself（反転） | P17: 一人旅は「本音」まで踏み込むと伸びるかの検証 | W17: =IF(Q17>0,(R17+S17+T17)/Q17,"")
A18: 14 | B18: =設定・結論!$B$4+13 -> 46321 | C18: 21:00 | D18: ノート実演 | E18: 浅 | F18: 3分本音ノート（保存型） | G18: 感謝ノートを3年書いても変わらなかった私が、3分で頭を静かにできた書き方。 | H18: 「ネガティブは書かない方がいい」と思っている人ほど、ノートが続かない。 | I18: ネガティブが強い人向け、3分でできる本音ノート。保存して今夜やって。 | J18: ポジティブになれない人専用 3分本音ノート ①1分：人のせい・嫉妬・悪口を全部書く ②30秒：一番強い感情を1語で丸 ③30秒：「事実」と「想像」に線を引く ④30秒：今日“あった”ものを3つ ⑤30秒：本当はどうしてほしかった？ | K18: ポイントは 「書いた内容で自分を裁かない」こと。 性格の悪い言葉が出てくるのは、 それだけ我慢してきた証拠。 これを2週間やったら、 妄想（イメージング）に雑念が入りにくくなった。 妄想のやり方は、またまとめるね。 | L18: やってみたら、①で一番多く出てきた言葉を教えて。 | M18: 3分本音ノートのテンプレはプロフィールのリンクから | N18: S3 保存型リスト | O18: @mirai.melife 275,597閲覧（質問リスト） | P18: Day3との比較・保存数・プロフ遷移 | W18: =IF(Q18>0,(R18+S18+T18)/Q18,"")
A19: 15 | B19: =設定・結論!$B$4+14 -> 46322 | C19: 21:00 | D19: 界隈への違和感 | E19: 深 | F19: スピ界隈の言葉で片づけない | G19: 「それは宇宙からのお試しよ」と言われた仲間は、半年たっても戻ってこなかった。 | H19: 苦しみを「宇宙のお試し」で片づけるのは、優しさじゃない。 | I19: 講座で一番優秀だった人が、ある日から来なくなった。 | J19: 講座で一番優秀だったメンバーが、 旦那さんと揉めて来られなくなった。 先生は言った。 「それは宇宙からのお試しなのよ」 その人は、半年たっても戻ってこなかった。 | K19: 苦しい時に必要だったのは、 きれいな意味づけじゃなくて 「それはしんどいね」の一言だったと思う。 だから私は、 意味を探す前に、まず全部吐き出していいと伝えたい。 意味づけは、ずっと後でいい。 | L19: スピ系・自己啓発で言われて一番モヤッとした言葉は？ | M19: なし | N19: S8 秘密暴露型 | O19: @mikari_neisan 31,054閲覧（界隈への皮肉） | P19: 界隈批判の拡散力（リポスト） | W19: =IF(Q19>0,(R19+S19+T19)/Q19,"")
A20: 16 | B20: =設定・結論!$B$4+15 -> 46323 | C20: 22:00 | D20: 本音暴露 | E20: 深 | F20: 人の幸せを喜べない | G20: 友達の「結婚しました」に、おめでとうより先に舌打ちが出た。 | H20: 人の幸せを喜べない人は、性格が悪いんじゃない。 | I20: インスタの幸せ報告を、そっと非表示にしたことがある。 | J20: 人の幸せを喜べない。 それは性格が悪いからじゃない。 自分の欲しいものを ずっと我慢してきた証拠。 嫉妬は、欲しいものの地図。 舌打ちは、本音のサイン。 | K20: 私は嫉妬を消そうとするのをやめた。 ノートに書く。 「本当はムカつく」 「私だって欲しかった」 そのあとに1行だけ。 「私が本当に欲しいのは何？」 嫉妬した相手は、 私の“次の妄想”の見本になった。 | L20: 最近、正直に嫉妬したことある？誰かじゃなくて「何に」で教えて。 | M20: なし | N20: S7 短文反転連打型 | O20: @yama_reself 125,641閲覧（短文反転） | P20: 短文型 vs 物語型の比較 | W20: =IF(Q20>0,(R20+S20+T20)/Q20,"")
A21: 17 | B21: =設定・結論!$B$4+16 -> 46324 | C21: 22:30 | D21: 恋愛（依存） | E21: 浅 | F21: 既読スルーの夜 | G21: 既読スルー3日目。私はスマホを1日47回見ていた。 | H21: 既読スルーで病むのは、相手のせいじゃない。 | I21: 「既読」の2文字で、自分の価値まで下がった気がした。 | J21: 既読スルーされた夜にやってほしい、 3つの質問。 ①今、何が一番怖い？ （嫌われた？忘れられた？） ②それは「事実」？「想像」？ ③彼が返信しなくても、今日の私にある“いいもの”は？ | K21: 既読スルーで苦しいのは、 彼の返信がないからじゃなく、 「返信がない＝私には価値がない」 と頭の中で翻訳してしまうから。 翻訳を止めるには、 頭の中から紙の上に出すのが一番早かった。 | L21: スマホを見る回数、1日何回くらいだった？ | M21: なし | N21: S1 リスト実用型 | O21: @sora411114（恋愛不安・ぐるぐる） | P21: 恋愛×ノートの保存需要 | W21: =IF(Q21>0,(R21+S21+T21)/Q21,"")
A22: 18 | B22: =設定・結論!$B$4+17 -> 46325 | C22: 07:30 | D22: ノート実演 | E22: 浅 | F22: 「ある」探しをお金で | G22: 「ないもの」ばかり数えていた私が、通帳じゃなく領収書を見て泣いた。 | H22: 「あるを探せ」と言われて幸せを探すから、見つからない。 | I22: 今月も家賃を払えた。それをノートに書いた日、何かが変わった。 | J22: 「あるを見つけましょう」 そう言われても、ないものしか見えなかった。 収入を増やしたい。 貯金が足りない。 だから探し方を変えた。 幸せじゃなくて、生活費で探す。 | K22: 今月払えたもの、書いてみた。 家賃。電気代。スマホ代。 子どもの給食費。 コンビニのコーヒー。 「全部、払えてるじゃん」 目に見える“ある”は、嘘がつけない。 だから私の潜在意識も、反論してこなかった。 | L22: 今月払えたもの、1つ書いて。小さいものでOK。 | M22: 「ある」探しテンプレはプロフィールから | N22: S1 場面告白型 | O22: 倫子さん独自メソッド（壁打ち：あるを認めるワーク） | P22: コメント参加型の伸び | W22: =IF(Q22>0,(R22+S22+T22)/Q22,"")
A23: 19 | B23: =設定・結論!$B$4+18 -> 46326 | C23: 21:00 | D23: 本音暴露 | E23: 浅 | F23: 「大丈夫です」が口癖 | G23: 「大丈夫です」が口癖だった頃、全然大丈夫じゃなかった。 | H23: 「大丈夫？」と聞かれて「大丈夫」と答える人ほど、限界が近い。 | I23: あなたは何個当てはまる？「大丈夫なふり」チェック | J23: 「大丈夫なふり」チェック □ 体調が悪くても「大丈夫です」 □ 頼まれたら即「やります」 □ 何もしてないのに「怒ってる？」と聞かれる □ 疲れていても笑顔で返信 □ 一人になると急にぐったり | K23: 3つ以上当てはまる人は、 優しいんじゃなく、たぶん怖いだけ。 本音を言ったら、関係が壊れる気がしてる。 私は5つ全部だった。 そして身体が先に限界を教えてくれた。 今日は1回だけ「ちょっと無理かも」と言ってみて。 | L23: いくつ当てはまった？数字だけでOK。 | M23: 「大丈夫なふり」を卒業するノートの書き方は固定投稿に | N23: S5 診断チェック型 | O23: @asa_jikorikai 322,106閲覧（問いリスト） | P23: 診断型のコメント数 | W23: =IF(Q23>0,(R23+S23+T23)/Q23,"")
A24: 20 | B24: =設定・結論!$B$4+19 -> 46327 | C24: 12:15 | D24: 界隈への違和感 | E24: 浅 | F24: 波動を上げなきゃ疲れ | G24: 「波動を上げなきゃ」と思った瞬間、私の波動はいちばん下がっていた。 | H24: 波動を上げようとするほど、波動は下がる。 | I24: イライラしている自分に「波動が下がる！」と焦って、さらにイライラした。 | J24: 波動を上げなきゃ。 いい気分でいなきゃ。 ネガティブに負けちゃダメ。 頑張るほど、苦しくなる。 焦るほど、ネガティブが増える。 上げようとするほど、下がる。 消そうとするほど、残る。 | K24: 逆にしたら、楽になった。 イライラは、出していい。 ムカつきは、書いていい。 出しきった後の“からっぽ”が、 私にとっての一番いい波動だった。 「いい気分でいなきゃ」は、私の新しい呪いだった。 | L24: 「〜しなきゃ」で一番しんどかったスピ・自己啓発ルールは？ | M24: なし | N24: S7 短文反転連打型 | O24: @yama_reself（この世界は、ぜんぶ逆） | P24: 界隈あるある共感の拡散 | W24: =IF(Q24>0,(R24+S24+T24)/Q24,"")
A25: 21 | B25: =設定・結論!$B$4+20 -> 46328 | C25: 21:00 | D25: 妄想への橋渡し | E25: 深 | F25: 妄想中の雑念 | G25: 妄想しようとすると、昔言われた悪口が割り込んでくる。それが私の毎日だった。 | H25: 妄想がうまくいかないのは、想像力が足りないからじゃない。 | I25: 目を閉じて、叶った自分を思い浮かべた。3秒後、「お前には無理」という声がした。 | J25: 叶った未来を妄想しようとすると、 頭の中で声がする。 「どうせ無理」 「あの時もダメだったじゃん」 「あんたなんか」 昔言われ続けた言葉が、 妄想のど真ん中に割り込んでくる。 | K25: だから私は、妄想の前に“毒出し”をする。 割り込んでくる声を、先に全部書く。 「誰に言われた言葉？」まで書く。 それが自分の声じゃないとわかると、 妄想の世界に入れるようになった。 妄想が下手なんじゃない。 先に片づけるものがあっただけ。 | L25: 妄想中に聞こえる「あの声」、誰の声？ | M25: 妄想に入る前の準備はプロフィールのノート術にまとめてます | N25: S2 告白反転型 | O25: @reirei_aoyama 203,554閲覧（潜在意識×身体反応） | P25: 妄想テーマへの移行期の反応 | W25: =IF(Q25>0,(R25+S25+T25)/Q25,"")
A26: 22 | B26: =設定・結論!$B$4+21 -> 46329 | C26: 21:00 | D26: 本音暴露 | E26: 浅 | F26: 断った後の罪悪感 | G26: 誘いを断ったあと、相手のLINEのアイコンを5回見に行った。 | H26: 断れないのは優しいからじゃない。嫌われた後を想像しすぎるから。 | I26: 「ごめん、その日は無理」送信。そこから1時間、スマホを裏返せなかった。 | J26: 断れない人チェック □ 断る理由を3つ用意してから送る □ 送った後、既読がつくまで落ち着かない □ 相手のSNSを見て怒ってないか確認 □ 次に会う時、余計に気を遣う □ 結局「やっぱり行ける」と言ってしまう | K26: 私は全部やってた。 断ることより、 断った後の“頭の中の裁判”が長かった。 今はシンプル。 「行きたくない」は理由にしていい。 断った後の罪悪感は、ノートに出す。 「本当は、何が怖い？」 | L26: いくつ当てはまった？断った後にやっちゃうこと、他にもある？ | M26: なし | N26: S5 診断チェック型 | O26: @asa_jikorikai（他人軸×問い） | P26: 浅い悩みの診断型 再現性 | W26: =IF(Q26>0,(R26+S26+T26)/Q26,"")
A27: 23 | B27: =設定・結論!$B$4+22 -> 46330 | C27: 21:00 | D27: 界隈への違和感 | E27: 深 | F27: 大きな願望と現実のギャップ | G27: 貯金300万円の現実が、1億円の妄想を毎回笑ってくる。 | H27: 引き寄せ初心者のビギナーズラックは、浅いところしか変わっていない。 | I27: 「年収が100万上がりました」は、潜在意識の力じゃないと思っている。 | J27: 妄想の中では1億円。 目を開けたら貯金300万円。 リアルの方が強すぎて、 脳が毎回「はいはい」って笑ってくる。 引き寄せを始めた最初は、 小さなことは叶う。ビギナーズラック。 でも深いところは、そのままだった。 | K27: 気づいたのは、 “1日3分の妄想”じゃ現実に勝てないこと。 まず現実の不安を全部吐き出す。 今“ある”ものを認める。 それから、リアル以上にリアルな妄想に浸る。 順番を守った人だけが、 コンフォートゾーンを抜けていく気がする。（私の実感です） | L27: 妄想の中の金額と現実の金額、差はどれくらい？ | M27: なし | N27: S8 秘密暴露型 | O27: @ruri_reishi888 150,855閲覧（引き寄せの誤解） | P27: 大願望テーマの信頼性リスク確認（コメントの質） | W27: =IF(Q27>0,(R27+S27+T27)/Q27,"")
A28: 24 | B28: =設定・結論!$B$4+23 -> 46331 | C28: 22:30 | D28: 恋愛（依存） | E28: 深 | F28: 他人軸の恋愛 | G28: 彼の気持ちは占いで10回聞いた。自分の気持ちは、1回も聞いていなかった。 | H28: 「彼は私をどう思ってる？」を考える人ほど、恋愛がうまくいかない。 | I28: 彼のSNSを開いては閉じて、を朝まで繰り返していた。 | J28: 「彼は私のこと、どう思ってる？」 この質問ばかりしていた頃、 私の恋愛はずっと苦しかった。 占い、タロット、友達、SNS。 彼の気持ちを知る方法は全部試した。 | K28: でも一度も 「私は、彼とどうなりたい？」 を聞いていなかった。 戻りたいのか、 拒絶された自分を取り戻したいのか。 それすら分からなかった。 恋愛の妄想は、 “彼の気持ち”じゃなく“私の気持ち”から始める。 | L28: 今の恋愛で、本当はどうしたい？1行でいいから書いてみて。 | M28: 恋愛の本音ノートは個別相談でも一緒に書いています（プロフィールから） | N28: S1 場面告白型 | O28: @sora411114（恋愛不安×自分軸） | P28: 恋愛層→個別相談の導線テスト | W28: =IF(Q28>0,(R28+S28+T28)/Q28,"")
A29: 25 | B29: =設定・結論!$B$4+24 -> 46332 | C29: 21:00 | D29: 本音暴露 | E29: 深 | F29: 詐欺被害・人の親切が怖い | G29: 700万円をだまし取られてから、人の親切まで怖くなった。 | H29: 「人を信じられない」のは、心が弱いからじゃない。 | I29: 優しくされると「何が目的？」と考えるようになった。 | J29: 700万円を失った。 お金より失ったのは、 人の親切を受け取る力だった。 優しくされると「何が目的？」 褒められると「何か売られる？」 人を信じない方が、安全だと思ってた。 | K29: でも、誰も信じない毎日は すごく静かで、すごく寂しかった。 人を信じる前に、まず 「自分の感覚」を信じ直すところから始めた。 毎晩ノートに、今日の“違和感”と“安心”を1つずつ。 それだけで、人を見る目が戻ってきた。 | L29: 人を信じられなくなったきっかけ、ある？言える範囲で。 | M29: なし | N29: S2 告白反転型 | O29: @chihochihoko 121,845閲覧（強い主張×体験） | P29: 深い悩みへの共感・DM発生 | W29: =IF(Q29>0,(R29+S29+T29)/Q29,"")
A30: 26 | B30: =設定・結論!$B$4+25 -> 46333 | C30: 07:30 | D30: ノート実演 | E30: 浅 | F30: 感情と事実を分ける | G30: 「嫌われた」と思った出来事、事実だけ書いたら2行しかなかった。 | H30: 「嫌われたかも」の9割は、事実じゃなく脚本。 | I30: 上司の「ちょっといい？」で、私の頭の中では解雇まで進んでいた。 | J30: 「嫌われたかも」と思った時のノート術。 左：事実 「既読がついて半日返信がない」 右：頭の中のストーリー 「怒らせた」「もう誘われない」「私が悪い」「みんなに言われてる」 | K30: 左は1行。右は止まらない。 苦しいのは出来事じゃなく、 右側の“脚本”の方だった。 脚本は、消さなくていい。 書いて「これは脚本」とラベルを貼るだけ。 それだけで、頭の中の音量が半分になる。 | L30: 最近「嫌われたかも」と思った出来事、事実だけで書くと何行？ | M30: 事実と脚本を分けるノートは固定投稿にまとめてます | N30: S1 リスト実用型 | O30: @sora411114（思考と身体の不一致） | P30: 保存型ノウハウの朝投稿 | W30: =IF(Q30>0,(R30+S30+T30)/Q30,"")
A31: 27 | B31: =設定・結論!$B$4+26 -> 46334 | C31: 21:00 | D31: 界隈への違和感 | E31: 深 | F31: 自愛のつもりで自分を監視 | G31: 「自分を愛しましょう」を頑張った結果、私は自分を24時間監視していた。 | H31: 自愛を頑張るほど、自分を責めるのが上手になる。 | I31: 「あ、今ネガティブ思考した」と気づくたび、ダメ出ししていた。 | J31: 自分を愛そう。 ネガティブ禁止。 今の言葉、自己否定だった。 あ、また人と比べた。 自愛してるつもりで、 私は自分を24時間監視していた。 愛してたんじゃない。 採点してた。 | K31: 本当の自愛は、たぶんもっと雑。 「性格悪いこと考えたな、まぁいっか」 どんな悪魔みたいな思考が出ても、 否定しない。直そうとしない。 ノートに書いて、閉じる。 それだけで、自分といるのが楽になった。 | L31: 自分にかけてた「ダメ出し」、一番多かったのは？ | M31: なし | N31: S7 短文反転連打型 | O31: @mikari_neisan（整ったふり） | P31: 自愛テーマの共感 | W31: =IF(Q31>0,(R31+S31+T31)/Q31,"")
A32: 28 | B32: =設定・結論!$B$4+27 -> 46335 | C32: 21:00 | D32: 妄想への橋渡し | E32: 浅 | F32: 妄想（イメージング）のやり方 | G32: 毒を全部吐いたあとにやる妄想は、同じ3分でも濃さがまったく違った。 | H32: 妄想は「目を閉じて想像する」だけじゃ足りない。 | I32: ネガティブが強い人のための、妄想の3ステップ。保存版。 | J32: 吐き出した後にやる、妄想の3ステップ ①場所を決める（どこにいる？朝？夜？） ②五感を1つずつ足す（匂い・音・手ざわり） ③“その時の私のひと言”を声に出す 「やっぱりね、知ってた」 | K32: コツは、 叶った瞬間じゃなく “叶った後の普通の日”を描くこと。 1億円入った瞬間より、 1億円ある生活の、なんでもない火曜日。 先に毒を出しておくと、 雑念が入らずにここまで浸れる。 | L32: 叶った後の「なんでもない火曜日」、あなたは何してる？ | M32: 吐く→ある→妄想の全ステップはプロフィールのリンクから | N32: S3 保存型リスト | O32: @reirei_aoyama（3ステップ×即効性） | P32: 妄想ノウハウの保存・プロフ遷移 | W32: =IF(Q32>0,(R32+S32+T32)/Q32,"")
A33: 29 | B33: =設定・結論!$B$4+28 -> 46336 | C33: 21:00 | D33: 本音暴露 | E33: 深 | F33: いい人をやめる | G33: 性格の悪い本音を認めた日から、いい人を演じる必要がなくなった。 | H33: 「いい人」をやめた方が、人間関係はうまくいく。 | I33: 「いい人ですね」と言われるたび、心の中で舌打ちしていた。 | J33: 「いい人ですね」 そう言われるたび、内心は 「疲れてるんだけど」だった。 人をランク付けして、 上の人には気を遣い、 下だと思った人を見下して。 そんな自分が一番嫌いだった。 | K33: でも、ランク付けをやめたら 自分のランクも気にならなくなった。 損得じゃなく、自分の感情で選ぶ。 否定してくる人は、華麗にスルー。 性格の悪い本音を認めたら、 いい人のふりをしなくてよくなった。 | L33: 「いい人」をやめたいこと、1つ挙げるなら？ | M33: なし | N33: S1 場面告白型 | O33: @yama_reself（受け取り・遠慮） | P33: 本音暴露の総括・フォロー転換 | W33: =IF(Q33>0,(R33+S33+T33)/Q33,"")
A34: 30 | B34: =設定・結論!$B$4+29 -> 46337 | C34: 21:00 | D34: 妄想への橋渡し | E34: 深 | F34: 30日の総まとめ→個別相談 | G34: 私が変わったのは、ポジティブになれた日じゃなかった。 | H34: 超ネガティブな人は、ポジティブにならなくても変われる。 | I34: 毎日泣いていた私が、泣かずに過去を話せるようになった。その間にやったこと。 | J34: 私が変わったのは、 ポジティブになれた日じゃない。 ノートに「ふざけんな」と書けた日。 人の幸せに嫉妬した自分を許せた日。 行きたくない食事を断れた日。 ネガティブを消さずに、出しきった日だった。 | K34: 吐く → 分ける → あるを見る → 望む → 妄想する この順番で、私は自分を取り戻してきた。 一人でノートを書くのがしんどい人へ。 個別相談で、あなたの本音を一緒に書き出すところから伴走しています。 詳細はプロフィールから。 | L34: この30日で、一番刺さった投稿を教えてください。 | M34: 個別相談（伴走型コーチング）の案内はプロフィールのリンクから | N34: S4 連載総まとめ型 | O34: @mirai.melife（ノウハウ→商品導線） | P34: 個別相談申込数 | W34: =IF(Q34>0,(R34+S34+T34)/Q34,"")
A36: ※ 反応率＝（いいね＋返信＋リポスト）÷閲覧。5％以上は緑表示。閲覧3,000超 or 反応率5％超のテーマは「バズ投稿100」から同カテゴリを追加投入。
A37: ※ Day4・12などの健康／メンタルに触れる投稿は、注意書き（医療機関・専門家への相談）を残してください。

Sheet 構造パターン
A1: 投稿構造パターン｜プロフィールクリックまでの順番
A2: 標準構造（S1）以外に、競合バズ投稿でプロフ遷移が想定される別構造を提示
A4: 構造 | B4: 文章の順番 | C4: プロフィールクリックへの効き方 | D4: 使った投稿例 | E4: 参考
A5: S1 標準：場面告白型 | B5: ①衝撃の冒頭（事実）→②具体的な場面→③その時の性格の悪い本音→④気づき（反転）→⑤今日できる1つ→⑥コメント質問 | C5: 共感→自分ごと化。コメントは増えるが、プロフ遷移は「この人の他の投稿も読みたい」次第 | D5: 焼肉／消しゴム／占い | E5: 現アカ1・2位
A6: S2 告白反転型 | B6: ①常識に反する告白（〜したのに変わらなかった）→②やったことの具体→③本当の原因（反転）→④倫子式の順番を1行で→⑤質問 | C6: 「この人だけ違うことを言う」でプロフを見に来る。差別化が最も効く | D6: アファメーション3年／脳梗塞 | E6: @sora411114・旧アカ1位
A7: S3 ランキング・保存型 | B7: ①数字・実績フック→②🥉やめとけ→🥈無難→🥇本当に効く→③🥇の手順3つ→④「保存して今夜」→⑤テンプレはプロフから | C7: 保存数とプロフ遷移が最も伸びやすい。テンプレ配布で受け皿を作る | D7: ジャーナリング何を書く／3分ノート | E7: @grit_power00・@mirai.melife
A8: S4 連載・未完ループ型 | B8: ①シリーズ名＋衝撃の一言→②物語の山場まで書く→③答えを書かずに「（1/3）続きはプロフから」 | C8: ★標準構造と異なりプロフ遷移を“前提”にする構造。続きを固定投稿・ハイライトに置くとクリック率が上がる | D8: 講座落ちこぼれ編／30日総まとめ | E8: @yamakawa.nobuto（未完の一行）
A9: S5 診断チェック型 | B9: ①「あなたは何個当てはまる？」→②□チェック5つ→③3つ以上の人の正体→④自分は全部だった告白→⑤今日の1つ→⑥数字だけコメント | C9: コメントのハードルが最低（数字だけ）。返信数→アルゴリズム拡散。プロフに「タイプ別の処方箋」を置くと遷移 | D9: 大丈夫なふり／断れない | E9: @asa_jikorikai 32万
A10: S6 Q&A・反論型 | B10: ①よくある反論を冒頭に（「書くと逆に苦しくなる」）→②半分正解と認める→③足りなかった1工程→④手順→⑤どっち派？ | C10: 信頼構築。専門性が伝わりフォロー転換が高い | D10: 吐き出しの注意点 | E10: @grit_power00への設計回答
A11: S7 短文反転連打型 | B11: ①短い反転文を4〜6行連打（上げるほど下がる等）→②最後に一番大事な答え→③今日1回の行動 | C11: 読了率が最も高い。リポストされやすい | D11: 人の幸せを喜べない／波動 | E11: @yama_reself 12.5万
A12: S8 秘密暴露型 | B12: ①「どうせ最後まで読む人は少ないので本当のことを書きます」→②界隈の常識否定→③生々しいお金・人間関係の流れ→④自分が選び直した基準 | C12: 読了率↑・最後まで読んだ人がプロフへ。月2〜3回まで（多用すると型がバレる） | D12: ワクワクで貯金を溶かした／感謝より本音 | E12: @fufu___life 6万
A14: ■ 冒頭の作り方（衝撃の事実／常識破壊）
A15: 型 | B15: 作り方 | C15: 例
A16: 衝撃の事実（数字） | B16: 具体的な数字＋行動 | C16: 「1週間で占いに8回お金を払った」「スマホを1日47回見ていた」
A17: 衝撃の事実（身体） | B17: 身体に出た代償 | C17: 「脳梗塞で入院した時、初めて顔色を読まなくてよかった」
A18: 衝撃の事実（恥） | B18: 言いたくない失敗・評価 | C18: 「潜在意識の先生に『もう教えられない』と言われた」
A19: 常識破壊（否定） | B19: 界隈の定説＋は〇〇じゃない | C19: 「アファメーションが効かないのは、回数が足りないからじゃない」
A20: 常識破壊（逆説） | B20: 〜するほど〜できない | C20: 「自愛を頑張るほど、自分を責めるのが上手になる」
A21: 常識破壊（再定義） | B21: ほめられる特徴＝実は苦しさ | C21: 「気が利く人は、才能じゃなくて生き延びるための癖だった」
A22: NG冒頭 | B22: 説明・一般論・挨拶から入る | C22: 「今日は潜在意識について話します」「人に頼れないのは0か100思考だから」

Sheet 分析まとめ
A1: ❶当たっているテーマ／当たっていないテーマ ❷改善点
A2: ChatGPTレポートの実測値・分析を整理
A4: ■ 自アカウント実績（@rinko_mind／@kokoro.rinko.1006）
A5: 順位 | B5: アカウント | C5: 冒頭 | D5: 閲覧 | E5: 判定 | F5: 勝因・敗因
A6: 1 | B6: 現 | C6: 脳梗塞で入院した時、初めて「誰かの顔色を読まなくていい時間」ができた | D6: 1137 | E6: 強い | F6: 身体の代償×言えない本音
A7: 2 | B7: 現 | C7: 「自分でやった方が早い」は、優秀さじゃない | D7: 728 | E7: 強い | F7: ほめられる特徴の反転
A8: 3 | B8: 現 | C8: 「私がやります」と言い続けて、脳梗塞になった | D8: 356 | E8: 中 | F8: 1位と同ネタだが冒頭が説明的
A9: 4 | B9: 現 | C9: 伊勢神宮に誘った。1週間、既読スルーだった | D9: 193 | E9: 中〜弱 | F9: 出来事止まりで本音まで届いていない
A10: 5 | B10: 現 | C10: 「人に頼れない」のは、0か100でしか考えられないから | D10: 182 | E10: 弱い | F10: 一般論・解説から入った
A11: 6 | B11: 現 | C11: 「私がやります」が口癖の人ほど、人を信用していません | D11: 152 | E11: 弱い | F11: 読者を責める印象
A12: 旧1 | B12: 旧 | C12: 「ありがとう」「大丈夫」「私はできる」を3年唱えても現実は1ミリも変わらなかった | D12: 1511 | E12: 強い | F12: 界隈の常識を自分の失敗で壊す
A14: ■ 当たっているテーマ／当たっていないテーマ
A15: 区分 | B15: テーマ | C15: 理由・使い方
A16: 当たる | B16: 身体が先に限界を知らせた話 | C16: 脳梗塞・頭痛・胸のザワザワ。抽象論より身体の事実が信頼を作る
A17: 当たる | B17: “いい人・しっかりした人”の裏側 | C17: 顔色を読む・頼れない・大丈夫なふり。ほめられる特徴を苦しさに反転
A18: 当たる | B18: 潜在意識界隈の定説に失敗した話 | C18: アファメーション・感謝・波動・手放し・ワクワク。「やった、でも効かなかった」
A19: 当たる | B19: 他人軸から戻る具体的場面 | C19: 行きたくない食事・一人で店に入れない・ママ友を避ける
A20: 当たる | B20: 人には言えない性格の悪い本音 | C20: 「感謝より自分で稼いだ私最高」「先生にムカつく」
A21: 弱い | B21: 抽象的な潜在意識論 | C21: 願い方・前提・思考は現実化だけでは競合と同じ
A22: 弱い | B22: 一般論から入る投稿 | C22: 「0か100思考」より「消しゴムは借りられる」の方が強い
A23: 弱い | B23: 毎回同じ5〜6連投の型 | C23: 問題提起→解説→幼少期→3ステップ→LINE。2〜3投稿で完結させる
A24: 弱い | B24: 毎投稿のLINE誘導 | C24: 共感前に売られている印象。通常はコメント誘導、固定投稿だけ導線
A25: 弱い | B25: 願望スケールを煽るだけ | C25: 「年収200万→1億」は信頼リスク。第二段階（Day23以降）に置く
A27: ■ ❷ 改善すべき点
A28: # | B28: 改善点 | C28: 具体策
A29: 1 | B29: コンセプトを「潜在意識」→「超ネガティブ向けの順番」へ | C29: 吐く→名前をつける→現実に戻る→望みを選ぶ→妄想する、を倫子式として固定
A30: 2 | B30: 「シネシネワーク」の表の名称を変える | C30: 毒出し3分／誰にも見せない本音ノート。体験談の中でのみ元の名前を出す
A31: 3 | B31: 吐き出しっぱなしにしない | C31: 7ステップ（設定・結論シート参照）で「吐く」と「書き換え」を一本の線に
A32: 4 | B32: 冒頭を説明ではなく告白・反転・場面に | C32: 「構造パターン」シートの冒頭の型を使用
A33: 5 | B33: 1投稿1テーマ・2〜3投稿で完結 | C33: 本文①＋本文②の2投稿構成で統一（本スケジュール）
A34: 6 | B34: プロフィールを“得られる変化”中心に | C34: 設定・結論シートのプロフィール案
A35: 7 | B35: 医療・脳科学・潜在意識の断定を弱める | C35: 「私はこうだった」「役立つ人もいる」。表現的筆記の効果は人により異なるという研究もある

Sheet 競合バズ分析
A1: ❸ 同業他者のバズ投稿（3万閲覧以上）とコメント分析
A2: 数値はChatGPTレポート記載の調査時点の値（未再計測）
A4: アカウント | B4: 閲覧 | C4: いいね | D4: コメント | E4: テーマ | F4: 冒頭 | G4: 構造 | H4: URL | I4: いいね率
A5: @yamakawa.nobuto | B5: 425098 | C5: 759 | D5: 7 | E5: 潜在意識×問い | F5: ジョブズが亡くなる直前まで手帳に書いた一行 | G5: 権威→未完の一行→脳の説明→自分のどん底→1つの問い | H5: https://www.threads.com/@yamakawa.nobuto/post/DZ15tVykhlC | I5: =IFERROR(C5/B5,0) -> 0.0017854706
A6: @asa_jikorikai | B6: 322106 | C6: 2445 | D6: 16 | E6: 他人軸・自信 | F6: 海外論文で見つけて衝撃だった | G6: 常識否定→研究概念→5つの問い→夜2文ワーク | H6: https://www.threads.com/@asa_jikorikai/post/DbVfCkECiae | I6: =IFERROR(C6/B6,0) -> 0.0075906689
A7: @mirai.melife | B7: 275597 | C7: 2853 | D7: 47 | E7: ジャーナリング | F7: 900日続けて人生を変えた私が毎週書く6つの質問 | G7: 数字で実績→質問を隠す→画像・商品導線 | H7: https://www.threads.com/@mirai.melife/post/DTAgwXfE5Nz | I7: =IFERROR(C7/B7,0) -> 0.010352072
A8: @reirei_aoyama | B8: 203554 | C8: 2065 | D8: 51 | E8: 潜在意識・身体反応 | F8: 本当の願いか確かめる方法。簡単なのにゾッとするほど当たる | G8: 即効性→恐怖語→3ステップ→体験コメント増殖 | H8: https://www.threads.com/@reirei_aoyama/post/DeTwVLhk9LG | I8: =IFERROR(C8/B8,0) -> 0.010144728
A9: @meina_mama3018 | B9: 181108 | C9: 2287 | D9: 102 | E9: 自己肯定感・母子 | F9: 子どもへの接し方より、母親が自分をどう扱うか | G9: 脳科学権威→親の罪悪感→子への影響→自己受容 | H9: https://www.threads.com/@meina_mama3018/post/DKoTzlVJJ3_ | I9: =IFERROR(C9/B9,0) -> 0.012627824
A10: @ruri_reishi888 | B10: 150855 | C10: 455 | D10: 4 | E10: 引き寄せの誤解 | F10: 霊感が強い母が言っていました | G10: 身近な権威→高級品の真似ではない→未来の自分ならどう受け取るか | H10: https://www.threads.com/@ruri_reishi888/post/DaNa4RwEQOe | I10: =IFERROR(C10/B10,0) -> 0.0030161413
A11: @yama_reself | B11: 125641 | C11: 2481 | D11: 12 | E11: 受け取り・遠慮 | F11: この世界は、ぜんぶ逆 | G11: 短い反転文の連打→最後に答え→今日1回の行動 | H11: https://www.threads.com/@yama_reself/post/DawUoGxiZZT | I11: =IFERROR(C11/B11,0) -> 0.019746739
A12: @chihochihoko | B12: 121845 | C12: 3053 | D12: 55 | E12: ネガティブ感情・愛着 | F12: 日本人はネガティブ感情を調整できず家族にぶつける人が多い | G12: 社会への強い主張→理論→母子→境界線 | H12: https://www.threads.com/@chihochihoko/post/DdhUkyAE7xq | I12: =IFERROR(C12/B12,0) -> 0.025056424
A13: @grit_power00 | B13: 109121 | C13: 239 | D13: 2 | E13: ジャーナリング比較 | F13: 🥉やめとけ／🥈無難／🥇本当に効く | G13: ランキング→既存法を否定→問いの設計→商品導線 | H13: https://www.threads.com/@grit_power00/post/DbwhtUIDwC8 | I13: =IFERROR(C13/B13,0) -> 0.0021902292
A14: @fufu___life | B14: 59821 | C14: 1324 | D14: 31 | E14: お金・ワクワク疲れ | F14: どうせ最後まで読む人は少ないので、真実を書きます | G14: 秘密告白→界隈の常識否定→浪費の生々しい流れ→安心を選ぶ | H14: https://www.threads.com/@fufu___life/post/DaG9KHfEe7r | I14: =IFERROR(C14/B14,0) -> 0.022132696
A15: @sora411114 | B15: 42221 | C15: 303 | D15: 18 | E15: 内観しても変わらない | F15: 自分と向き合う人ほど自分軸は育ちにくい | G15: 逆説→思考と身体の不一致→変わらない3原因 | H15: https://www.threads.com/@sora411114/post/DU8CEFukZ5O | I15: =IFERROR(C15/B15,0) -> 0.0071765235
A16: @mikari_neisan | B16: 31054 | C16: 151 | D16: 29 | E16: 整ったふり | F16: 整ってる人が、いちばん闇抱えてる説 | G16: 界隈への皮肉→体の症状→「演じるな、感じろ」 | H16: https://www.threads.com/@mikari_neisan/post/DULlRvFEnUO | I16: =IFERROR(C16/B16,0) -> 0.0048624976
A18: ■ 勝ちパターン
A19: # | B19: パターン | C19: 例
A20: 1 | B20: 常識を否定する | C20: ワクワクより安心／向き合う人ほど自分軸が育たない／整っている人ほど闇
A21: 2 | B21: 最初に答えを少し隠す | C21: 「その一行は…」「本当の理由は…」
A22: 3 | B22: 権威か当事者性を1つだけ置く | C22: 論文・ジョブズ・母の言葉・900日
A23: 4 | B23: 抽象概念を身体・お金・家庭に落とす | C23: 胸がザワザワ・支払いが怖い・子どもに伝わる
A24: 5 | B24: 今すぐできる動作で終わる | C24: 一行書く・今日は安心を選ぶ
A26: ■ コメント欄の共通キーワード・悩み（公開取得できた範囲を全件読み取り）
A27: 区分 | B27: 内容
A28: 共感ワード | B28: 腑に落ちた／わかります／私も同じ／まさにそれ／やってみます／もっと早く知りたかった／モヤモヤが晴れる／安心したい／自分を大切にしたい／フラットがいい
A29: 表面の悩み | B29: 願いが本音かわからない／身体の反応がわからない／ジャーナリングで何を書けばいいかわからない／殴り書きでもいいのか／夫を頼れず一人で抱える／お金を使った後に絶望する／子どもに悪影響が怖い／ポジティブな人のノリについていけない／「考えすぎ」と言われるのがうざい
A30: 深い悩み | B30: 自分の感覚が正しいと信じられない／正しいやり方を外側に求め続ける／ネガティブな自分は迷惑／休む・断る・使わない＝敗北／母親として子を壊している罪悪感／頼ると価値が下がる・裏切られる／ポジティブの押し付け＝苦しさごと否定／学んでも変われず「私だけおかしい」
A31: 投稿への反映 | B31: Day7（何を書けばいい）・Day5（お金を使った後の絶望）・Day12（殴り書き・吐いて苦しい）・Day20（ポジティブ押し付け）・Day25（感覚を信じ直す）
A33: ■ 競合アカウント／他媒体（ノート・ジャーナリング×潜在意識×ネガティブ吐き出し）
A34: 名前 | B34: 媒体 | C34: 特徴 | D34: 倫子さんとの差別化
A35: @fufu___life | B35: Threads（2,725F） | C35: 引き寄せ界隈の常識を生活とお金の安心に翻訳。最も近い直接競合 | D35: 倫子さんは「超ネガティブ×ノート実演」で具体性を出す
A36: @sora411114 | B36: Threads（4,088F） | C36: 恋愛不安・ぐるぐる思考・愛着・身体感覚 | D36: 恋愛は依存体験（占い週8）で当事者性
A37: @mikari_neisan | B37: Threads（2,178F） | C37: 50代女性の整ったふり・本音・身体 | D37: 生々しい言葉の参考。倫子さんは順番（メソッド）を持つ
A38: @grit_power00 | B38: Threads（2,501F） | C38: 脳科学×ジャーナリング×収入。ランキング構成 | D38: 「吐くだけではダメ」→倫子式7ステップで回答
A39: @mirai.melife | B39: Threads（11,328F） | C39: ジャーナリング→仕事・商品導線が上手い | D39: テンプレ配布→個別相談の導線を参考に
A40: @asa_jikorikai | B40: Threads（14,581F） | C40: 研究・心理学を根拠に他人軸を問いに | D40: 診断チェック型の参考
A41: @reirei_aoyama | B41: Threads（643F） | C41: 簡単・即効・ゾッとするフック | D41: 少フォロワーでも冒頭で伸びる実例
A42: @chihochihoko | B42: Threads（11,572F） | C42: 社会への強い主張×海外経験 | D42: 長文でも主張の強さで読ませる
A43: カズ先生 | B43: note | C43: 潜在意識の書き換えノートは願望より本音を書く | D43: ほぼ同主張→倫子さんは「失敗した当事者」＋妄想まで
A44: SHIFT｜使える引き寄せ | B44: Podcast | C44: ムカつくならムカつくと認めて外に出しニュートラルへ | D44: 音声よりノート実演で差別化
...

Sheet 生々しいネタ
A1: ❹ 発信者ではなく「愚痴・恥・本音」で投稿できるネタ
A2: 型：きれいな結論を先に言わない→言いたくない事実→性格の悪い本音→「今ならこうする」を1つ
A4: No | B4: ネタ（愚痴・本音のまま） | C4: スケジュールでの使用
A5: 1 | B5: 潜在意識の講座で、私だけいつも怒られていた | C5: Day8
A6: 2 | B6: 先生に「もう教えられない。自己流でやりすぎ」と言われた | C6: Day8
A7: 3 | B7: 優秀な受講生と比べられるたび、落ちこぼれだと思った | C7: 未使用（31日目以降）
A8: 4 | B8: 感謝しなきゃと思っていた。本音は「私が稼いだ金で自由に来た私が最高」 | C8: Day11
A9: 5 | B9: ルンルンしなきゃ、ネガティブに負けちゃいけない、が一番しんどかった | C9: 未使用（31日目以降）
A10: 6 | B10: 3分妄想しても、残り23時間57分の現実に負けていた | C10: Day9
A11: 7 | B11: 貯金300万円がリアルすぎて、1億円の自分なんて脳が笑っていた | C11: Day23
A12: 8 | B12: 願えば放っておけば叶うと思っていた。全然放っておけなかった | C12: 未使用（31日目以降）
A13: 9 | B13: 一人旅を寂しいと思っていた。人と行く方がずっと気を遣って寂しかった | C13: Day13
A14: 10 | B14: ママ友を見つけたら、気づかれる前に反対方向へ歩く | C14: 未使用（31日目以降）
A15: 11 | B15: 一人で店に入るだけで「寂しい人と思われないか」を考えていた | C15: 未使用（31日目以降）
A16: 12 | B16: 60代のおじさんに誘われ、行きたくない焼肉に行った | C16: Day2
... A36: 32 | B36: 彼の連絡待ちの1週間で占いに8回 | C36: Day10

Sheet 浅い悩み・深い悩み
A1: ❺ 浅い悩み（本人が言葉にできる）と深い悩み（まだ言葉にできない）
A2: 浅い悩みで集客→深い悩みで信頼→個別相談。各行の「対応投稿」で30日スケジュールとの対応を確認
A4: No | B4: 浅い悩み | C4: 対応投稿 | D4: 深い悩み | E4: 対応投稿
A5: 1 | B5: 考えすぎて眠れない | C5: Day9・14 | D5: 役に立たない私は捨てられる | E5: Day6
A6: 2 | B6: 既読スルーが気になる | C6: Day17 | D6: 断ったら“悪い人”になる | E6: Day22
A7: 3 | B7: 人の顔色を見てしまう | C7: Day4 | D7: 頼むと無能だとバレる | E7: Day6
A8: 4 | B8: 頼れない・任せられない | C8: Day6 | D8: 任せると裏切られ、見る目のなさが証明される | E8: Day25
A9: 5 | B9: 誘いを断れない | C9: Day2・22 | D9: 休むと価値がなくなる | E9: Day4
A10: 6 | B10: 一人で行動できない | C10: Day13 | D10: 人の機嫌を読まないと危険なことが起きる | E10: Day4
A11: 7 | B11: ママ友・職場の人間関係で疲れる | C11: バズ100 | D11: 自分の感覚は間違っている→先生・占いに答えをもらう | E11: Day10・24
A12: 8 | B12: 人と比べて落ち込む | C12: Day16 | D12: ネガティブを認めたら悪い現実になる | E12: Day12
A13: 9 | B13: 感謝ノートが続かない | C13: Day3 | D13: 怒りを手放したら、ひどいことをされた事実まで無かったことになる | E13: Day15
A14: 10 | B14: ジャーナリングで何を書けばいいかわからない | C14: Day7 | D14: 幸せになったら今いる人から嫌われる | E14: Day11
A15: 11 | B15: 妄想・瞑想中に雑念が入る | C15: Day21 | D15: お金を持つと責められる・奪われる・騙される | E15: Day25
A16: 12 | B16: ポジティブになれない | C16: Day1・20 | D16: 一人で満たされると誰からも必要とされなくなる | E16: Day13
... A20: 16 | B20: 「ある」を見つけられない | C20: Day18 | D20: 「変わらない自分」の方が安全 | E20: Day30
A21: 17 | D21: 学びをやめたら何もない自分になる | E21: Day8
A22: 18 | D22: 自分で正解を決める責任が怖い | E22: Day11

Sheet 恋愛・復縁判定
A1: 恋愛（特に復縁）を中心ネタにするべきか
A2: 結論：復縁成就は中心にしない。恋愛依存・連絡待ち・占い依存は積極的に扱う（全体の10〜15％）
A4: テーマ | B4: 推奨度 | C4: 理由 | D4: 扱い方
A5: 復縁を叶える方法 | B5: 低 | C5: 本人に実績がなく、訴求と実績が一致しない。成果を約束すると信頼・クレームリスク | D5: 「戻るよね」とは言わない。相談は受けるが「自分の気持ちを取り戻す」支援として
A6: 既読スルーで病む心理 | B6: 高 | C6: 悩みが具体的で浅い悩みとして集客力が高い | D6: Day17：3つの質問ノート
A7: 占い依存・恋愛依存 | B7: 非常に高 | C7: 週8回の占い通いという強い当事者性 | D7: Day10：占い8回
A8: 執着・嫉妬・妄想 | B8: 高 | C8: ノート術・妄想への接続が自然 | D8: Day16・24
A9: 自分軸・本音の吐き出し | B9: 最優先 | C9: 恋愛以外の読者にも届く。恋愛層もここで拾える | D9: 全体の主軸
A10: 18禁妄想（成人向け動画を使うイメージング） | B10: 公開投稿NG | C10: Threadsの性的コンテンツ規約・配信抑制リスク、ブランド毀損 | D10: 個別相談内で、本人同意のうえ言葉を選んで扱う程度に留める
A12: ■ 復縁相談が来たときの言い換え
A13: NG（実績と矛盾） | B13: OK（倫子さんの当事者性で言える）
A14: 彼は戻ってきますよ | B14: 戻る・戻らないの前に、あなたが「本当はどうしたい」かを一緒に書き出そう
A15: 復縁を引き寄せる方法 | B15: 連絡を待つ夜を、自分を取り戻す夜に変える方法
A16: 私も復縁しました | B16: 私も占いに週8回行くほど、答えを外に探していた

Sheet バズ投稿100
A1: 新バズ投稿100（前回案と重複しない切り口）
A2: 冒頭A＝衝撃の事実／B＝常識破壊。構造は「構造パターン」シートのS1〜S8。31日目以降はここから補充
A4: No | B4: カテゴリ | C4: 深さ | D4: 冒頭A（衝撃の事実） | E4: 冒頭B（常識破壊） | F4: 構造 | G4: コメント誘導 | H4: 使用日・結果メモ
A5: 1 | B5: 本音暴露・性格の悪い私 | C5: 浅 | D5: 友達のランチの誘いを「仕事」と嘘をついて断り、家で一人でアイスを食べていた。 | E5: 断る理由に嘘をつくのは、優しさじゃなくて怖さ。 | F5: S1 | G5: 断るときについた嘘、ある？
A6: 2 | B6: 本音暴露・性格の悪い私 | C6: 深 | D6: 母に「あんたは手がかからない子」と言われ続けた。だから今も、誰にも手をかけてもらえない。 | E6: 「手のかからない子」は、褒め言葉じゃなかった。 | F6: S2 | G6: 子どもの頃に言われて、今も残ってる言葉は？
A7: 3 | B7: 本音暴露・性格の悪い私 | C7: 浅 | D7: グループLINEの返信を、30分かけて書き直して結局送らなかった。 | E7: 返信が遅い人は、雑なんじゃない。考えすぎてるだけ。 | F7: S1 | G7: LINEの下書き、何回消す？
A8: 4 | B8: 本音暴露・性格の悪い私 | C8: 深 | D8: 人が失敗した話を聞くと、少しだけホッとする自分がいる。 | E8: 人の不幸でホッとするのは、あなたが限界まで頑張ってる証拠。 | F8: S2 | G8: 言えないけど、ホッとした経験ある？
A9: 5 | B9: 本音暴露・性格の悪い私 | C9: 浅 | D9: ママ友を見つけたら、気づかれる前に反対方向へ歩いていた。 | E9: 人付き合いを避けるのは、人が嫌いだからじゃない。 | F9: S1 | G9: つい避けてしまう人、いる？
A10: 6 | B10: 本音暴露・性格の悪い私 | C10: 深 | D10: 「優しいね」と言われるたび、自分が空っぽになっていく気がした。 | E10: 優しい人ほど、自分にだけは冷たい。 | F10: S7 | G10: 自分にだけ厳しいこと、何？
A11: 7 | B11: 本音暴露・性格の悪い私 | C11: 浅 | D11: 会計のとき「ここは私が」と言いながら、帰り道で残高を計算していた。 | E11: おごるのが苦しい人は、ケチなんじゃない。 | F11: S1 | G11: 見栄で払ったこと、ある？
A12: 8 | B12: 本音暴露・性格の悪い私 | C12: 深 | D12: 褒められると、なぜか怒られるより居心地が悪い。 | E12: 褒め言葉を受け取れないのは、謙虚だからじゃない。 | F12: S2 | G12: 褒められたとき、何て返してる？
A13: 9 | B13: 本音暴露・性格の悪い私 | C13: 浅 | D13: 職場の飲み会、行かない理由を考えるのに1週間かかった。 | E13: 「行きたくない」は、それだけで立派な理由。 | F13: S5 | G13: 行きたくない集まり、今ある？
A14: 10 | B14: 本音暴露・性格の悪い私 | C14: 深 | D14: 親の老後を心配しているふりをして、本当は解放される日を待っていた。 | E14: 親を大事にできない自分を、責めなくていい。 | F14: S8 | G14: 家族に対して言えない本音、ある？
A15: 11 | B15: 本音暴露・性格の悪い私 | C15: 浅 | D15: SNSで「いいね」を押すかどうか、5分迷った。 | E15: 人の投稿に反応できないのは、性格が悪いからじゃない。 | F15: S1 | G15: いいね押すの、迷う人いる？
A16: 12 | B16: 本音暴露・性格の悪い私 | C16: 深 | D16: 謝られても許せない。許せない自分も許せない。 | E16: 「許さなきゃ前に進めない」は嘘だった。 | F16: S2 | G16: まだ許せてない人、いる？
... A104: 100 | B104: 身体・お金・人生の代償 | C104: 浅 | D104: 出雲大社の帰り道、「私、今幸せだ」と声に出していた。 | E104: 幸せは、引き寄せるより先に気づくもの。 | F104: S1 | G104: 最近「幸せ」と思った瞬間は？
